<?xml version="1.0" ?>
<!-- =================================================================================== -->
<!-- |    This document was autogenerated by xacro from youbot.urdf.xacro              | -->
<!-- |    EDITING THIS FILE BY HAND IS NOT RECOMMENDED                                 | -->
<!-- =================================================================================== -->
<robot name="youbot1" xmlns:xacro="http://ros.org/wiki/xacro">
  <!-- The following included files set up definitions of parts of the robot body -->
  <!-- misc common stuff? -->
  <!-- Casters -->
  <!-- youbot base -->
  <!-- sensors -->
  <!-- simplified box collision geometry for base -->
  <!-- youbot plate -->
  <!-- youbot arm -->
  &gt;

	
  <!-- common properties -->
  <!-- arm limits positions (deg) -->
  <!-- dynamic properties : mass (kg) Alu data sheet -->
  <!-- TODO: add inertia tensor-->
  <!-- youbot gripper -->
  <!-- common properties -->
  <!-- fingers limits, values are in meters -->
  <!-- joint state publisher -->
  <!-- Now we can start using the macros included above to define the actual youbot -->
  <link name="base_footprint1">
    <visual>
      <origin rpy="0 0 0" xyz="0 0 0"/>
      <geometry>
        <box size="0.001 0.001 0.001"/>
      </geometry>
      <material name="Red"/>
    </visual>
    <collision>
      <origin rpy="0 0 0" xyz="0 0 -0.05"/>
      <geometry>
        <box size="0.001 0.001 0.001"/>
      </geometry>
    </collision>
  </link>
  <joint name="base_footprint_joint" type="fixed">
    <origin rpy="0 0 0" xyz="0 0 0"/>
    <child link="base_link1"/>
    <parent link="base_footprint1"/>
  </joint>
  <link name="base_link1">
    <inertial>
      <mass value="22.0"/>
      <origin xyz="0 0 0"/>
      <inertia ixx="5.652232699207" ixy="-0.009719934438" ixz="1.293988226423" iyy="5.669473158652" iyz="-0.007379583694" izz="3.683196351726"/>
    </inertial>
    <visual>
      <origin rpy="0 0 0" xyz="0 0 0"/>
      <geometry>
        <mesh filename="package://luh_youbot_description/meshes/youbot_base/base.dae"/>
      </geometry>
      <material name="Black"/>
    </visual>
    <collision>
      <origin rpy="0 0 0" xyz="0 0 0"/>
      <geometry>
        <mesh filename="package://luh_youbot_description/meshes/youbot_base/base_convex_small.dae"/>
      </geometry>
    </collision>
  </link>
  <!-- base laser front -->
  <!-- <joint name="base_laser_front_hokuyo_urg04_laser_joint" type="fixed">
    <axis xyz="0 1 0"/>
    <origin rpy="0 0 0" xyz="0.309 0 -0.03"/>
    <parent link="base_link"/>
    <child link="base_laser_front_link"/>
  </joint> -->
  <!-- <link name="base_laser_front_link" type="laser">
    <inertial>
      <mass value="0.16"/>
      <origin rpy="0 0 0" xyz="0 0 0"/>
      <inertia ixx="0.1" ixy="0" ixz="0" iyy="0.1" iyz="0" izz="0.1"/>
    </inertial>
    <visual>
      <origin rpy="0 0 0" xyz="0 0 0"/>
      <geometry>
        <mesh filename="package://luh_youbot_description/meshes/sensors/hokuyo.dae"/>
      </geometry>
    </visual>
    <collision>
      <origin rpy="0 0 0" xyz="0 0 0"/>
      <geometry>
        <mesh filename="package://luh_youbot_description/meshes/sensors/hokuyo_convex.dae"/>
      </geometry>
    </collision>
  </link>-->
  <!-- gazebo extensions -->
  <!--<gazebo reference="base_laser_front_link">
    <sensor name="base_laser_front" type="ray">
      <pose>0 0 0 0 0 0</pose>
      <ray>
        <scan>
          <horizontal>
            <samples>640</samples>
            <resolution>1</resolution>
            <min_angle>-1.570000</min_angle>
            <max_angle>1.570000</max_angle>
          </horizontal>
        </scan>
        <range>
          <min>0.050000</min>
          <max>5.600000</max>
          <resolution>0.360000</resolution>
        </range>
      </ray>
      <always_on>true</always_on>
      <update_rate>10</update_rate>
      <visualize>false</visualize>
      <plugin filename="libgazebo_ros_laser.so" name="gazebo_ros_laser">
        <gaussianNoise>0.02</gaussianNoise>
        <alwaysOn>true</alwaysOn>
        <hokuyoMinIntensity>101</hokuyoMinIntensity>
        <updateRate>10</updateRate>
        <topicName>scan</topicName>
        <frameName>/base_laser_front_link</frameName>-->
        <!--interface:laser name="gazebo_ros_${name}_iface" /-->
      <!--</plugin>
    </sensor>
  </gazebo> -->
  <!-- base laser back -->
  <!-- <joint name="base_laser_back_hokuyo_urg04_laser_joint" type="fixed">
    <axis xyz="0 1 0"/>
    <origin rpy="0 0 3.14159265359" xyz="-0.309 0 -0.03"/>
    <parent link="base_link"/>
    <child link="base_laser_back_link"/>
  </joint> -->
  <!-- <link name="base_laser_back_link" type="laser">
    <inertial>
      <mass value="0.16"/>
      <origin rpy="0 0 0" xyz="0 0 0"/>
      <inertia ixx="0.1" ixy="0" ixz="0" iyy="0.1" iyz="0" izz="0.1"/>
    </inertial>
    <visual>
      <origin rpy="0 0 0" xyz="0 0 0"/>
      <geometry>
        <mesh filename="package://luh_youbot_description/meshes/sensors/hokuyo.dae"/>
      </geometry>
    </visual>
    <collision>
      <origin rpy="0 0 0" xyz="0 0 0"/>
      <geometry>
        <mesh filename="package://luh_youbot_description/meshes/sensors/hokuyo_convex.dae"/>
      </geometry>
    </collision>
  </link> -->
  <!-- gazebo extensions -->
  <!-- <gazebo reference="base_laser_back_link">
    <sensor name="base_laser_back" type="ray">
      <pose>0 0 0 0 0 0</pose>
      <ray>
        <scan>
          <horizontal>
            <samples>640</samples>
            <resolution>1</resolution>
            <min_angle>-1.570000</min_angle>
            <max_angle>1.570000</max_angle>
          </horizontal>
        </scan>
        <range>
          <min>0.050000</min>
          <max>5.600000</max>
          <resolution>0.360000</resolution>
        </range>
      </ray>
      <always_on>true</always_on>
      <update_rate>10</update_rate>
      <visualize>false</visualize>
      <plugin filename="libgazebo_ros_laser.so" name="gazebo_ros_laser">
        <gaussianNoise>0.02</gaussianNoise>
        <alwaysOn>true</alwaysOn>
        <hokuyoMinIntensity>101</hokuyoMinIntensity>
        <updateRate>10</updateRate>
        <topicName>scan_back</topicName>
        <frameName>/base_laser_back_link</frameName>-->
        <!--interface:laser name="gazebo_ros_${name}_iface" /-->
     <!--> </plugin>
    </sensor>
  </gazebo> -->-->
  <!-- front left wheel -->
  <joint name="wheel_joint_fl" type="continuous">
    <origin rpy="0 0 0" xyz="0.228 0.158 -0.034"/>
    <axis xyz="0 1 0"/>
    <limit effort="30" velocity="10"/>
    <dynamics damping="0.0" friction="0.0"/>
    <safety_controller k_velocity="10.0"/>
    <parent link="base_link1"/>
    <child link="wheel_link_fl"/>
  </joint>
  <link name="wheel_link_fl">
    <inertial>
      <mass value="0.4"/>
      <origin xyz="0 0 0"/>
      <inertia ixx="0.012411765597" ixy="-0.000711733678" ixz="0.00050272983" iyy="0.015218160428" iyz="-0.000004273467" izz="0.011763977943"/>
    </inertial>
    <visual>
      <origin rpy="0 0 0" xyz="0 0 0"/>
      <geometry>
        <mesh filename="package://luh_youbot_description/meshes/youbot_base/wheel1.dae"/>
      </geometry>
    </visual>
    <collision>
      <origin rpy="1.57079632679 0 0" xyz="0 0 0"/>
      <geometry>
        <cylinder length="0.07" radius="0.05"/>
      </geometry>
    </collision>
  </link>
  <!-- front right wheel -->
  <joint name="wheel_joint_fr" type="continuous">
    <origin rpy="0 0 0" xyz="0.228 -0.158 -0.034"/>
    <axis xyz="0 1 0"/>
    <limit effort="30" velocity="10"/>
    <dynamics damping="0.0" friction="0.0"/>
    <safety_controller k_velocity="10.0"/>
    <parent link="base_link1"/>
    <child link="wheel_link_fr"/>
  </joint>
  <link name="wheel_link_fr">
    <inertial>
      <mass value="0.4"/>
      <origin xyz="0 0 0"/>
      <inertia ixx="0.012411765597" ixy="-0.000711733678" ixz="0.00050272983" iyy="0.015218160428" iyz="-0.000004273467" izz="0.011763977943"/>
    </inertial>
    <visual>
      <origin rpy="0 0 0" xyz="0 0 0"/>
      <geometry>
        <mesh filename="package://luh_youbot_description/meshes/youbot_base/wheel2.dae"/>
      </geometry>
    </visual>
    <collision>
      <origin rpy="1.57079632679 0 0" xyz="0 0 0"/>
      <geometry>
        <cylinder length="0.07" radius="0.05"/>
      </geometry>
    </collision>
  </link>
  <!-- back left wheel -->
  <joint name="wheel_joint_bl" type="continuous">
    <origin rpy="0 0 0" xyz="-0.228 0.158 -0.034"/>
    <axis xyz="0 1 0"/>
    <limit effort="30" velocity="10"/>
    <dynamics damping="0.0" friction="0.0"/>
    <safety_controller k_velocity="10.0"/>
    <parent link="base_link1"/>
    <child link="wheel_link_bl"/>
  </joint>
  <link name="wheel_link_bl">
    <inertial>
      <mass value="0.4"/>
      <origin xyz="0 0 0"/>
      <inertia ixx="0.012411765597" ixy="-0.000711733678" ixz="0.00050272983" iyy="0.015218160428" iyz="-0.000004273467" izz="0.011763977943"/>
    </inertial>
    <visual>
      <origin rpy="0 0 0" xyz="0 0 0"/>
      <geometry>
        <mesh filename="package://luh_youbot_description/meshes/youbot_base/wheel2.dae"/>
      </geometry>
    </visual>
    <collision>
      <origin rpy="1.57079632679 0 0" xyz="0 0 0"/>
      <geometry>
        <cylinder length="0.07" radius="0.05"/>
      </geometry>
    </collision>
  </link>
  <!-- back right wheel -->
  <joint name="wheel_joint_br" type="continuous">
    <origin rpy="0 0 0" xyz="-0.228 -0.158 -0.034"/>
    <axis xyz="0 1 0"/>
    <limit effort="30" velocity="10"/>
    <dynamics damping="0.0" friction="0.0"/>
    <safety_controller k_velocity="10.0"/>
    <parent link="base_link1"/>
    <child link="wheel_link_br"/>
  </joint>
  <link name="wheel_link_br">
    <inertial>
      <mass value="0.4"/>
      <origin xyz="0 0 0"/>
      <inertia ixx="0.012411765597" ixy="-0.000711733678" ixz="0.00050272983" iyy="0.015218160428" iyz="-0.000004273467" izz="0.011763977943"/>
    </inertial>
    <visual>
      <origin rpy="0 0 0" xyz="0 0 0"/>
      <geometry>
        <mesh filename="package://luh_youbot_description/meshes/youbot_base/wheel1.dae"/>
      </geometry>
    </visual>
    <collision>
      <origin rpy="1.57079632679 0 0" xyz="0 0 0"/>
      <geometry>
        <cylinder length="0.07" radius="0.05"/>
      </geometry>
    </collision>
  </link>
  
  <gazebo>
    <plugin filename="libyoubot_base_1_controller.so" name="base_controller">
      <commandTopic_1>gazebo_1/cmd_vel</commandTopic_1>
      <odometryTopic_1>base1/odom</odometryTopic_1>
      <odometryFrame_1>base1/odom</odometryFrame_1>
      <odometryRate_1>20.0</odometryRate_1>
      <robotBaseFrame_1>base_footprint1</robotBaseFrame_1>
    </plugin>
  </gazebo>

  <!-- 
  <gazebo reference="base_link1">
    
    <sensor name="youbot_base_bumper" type="contact">
      <always_on>true</always_on>
      <update_rate>30.0</update_rate>
      <contact>
        <collision>base_link1_collision</collision>
      </contact>
      <plugin filename="libgazebo_ros_bumper.so" name="gripper_bumper">
        <bumperTopicName>youbot_base_bumper</bumperTopicName>
        <frameName>base_link1</frameName>
      </plugin>
    </sensor>
  </gazebo>
  -->
  <!-- joint between arm_7_link and sdh_palm_link -->
  <joint name="plate_joint" type="fixed">
    <origin rpy="0 0 0" xyz="-0.159 0 0.046"/>
    <parent link="base_link1"/>
    <child link="plate_link1"/>
  </joint>
  <link name="plate_link1">
    <inertial>
      <origin rpy="0 0 0" xyz="0 0 0"/>
      <mass value="1"/>
      <inertia ixx="0.01" ixy="0" ixz="0" iyy="0.01" iyz="0" izz="0.01"/>
    </inertial>
    <visual>
      <origin rpy="0 0 0" xyz="0 0 0"/>
      <geometry>
        <mesh filename="package://luh_youbot_description/meshes/youbot_plate/plate.dae"/>
      </geometry>
      <material name="DarkGrey"/>
    </visual>
    <collision>
      <origin rpy="0 0 0" xyz="0 0 0"/>
      <geometry>
        <mesh filename="package://luh_youbot_description/meshes/youbot_plate/plate_convex.dae"/>
      </geometry>
    </collision>
  </link>
  <!-- extensions -->
  <!-- joint between base_link and arm_0_link -->
  <joint name="arm1_joint_0" type="fixed">
    <origin rpy="0 0 0" xyz="0.143 0 0.046"/>
    <parent link="base_link1"/>
    <child link="arm1_link_0"/>
    <!--without Dynamics maybe causes jittering-->
    <dynamics damping="1" friction="1"/>
  </joint>
  <joint name="arm1_joint_origin" type="fixed">
    <origin rpy="0 0 0" xyz="0.024 0 0.0"/>
    <parent link="arm1_link_0"/>
    <child link="arm1_origin"/>
  </joint>
  <link name="arm1_origin"/>
  <link name="arm1_link_0">
    <inertial>
      <origin rpy="0 0 0" xyz="0 0 0"/>
      <!--<mass value="${link_0_mass}"/>-->
      <mass value="0.845"/>
      <inertia ixx="0.01" ixy="0" ixz="0" iyy="0.01" iyz="0" izz="0.01"/>
    </inertial>
    <visual>
      <origin rpy="0 0 0" xyz="0 0 0"/>
      <geometry>
        <mesh filename="package://luh_youbot_description/meshes/youbot_arm/arm0.dae"/>
      </geometry>
    </visual>
    <collision>
      <origin rpy="0 0 0" xyz="0 0 0"/>
      <geometry>
        <mesh filename="package://luh_youbot_description/meshes/youbot_arm/arm0_convex.dae"/>
      </geometry>
    </collision>
  </link>
  <!-- joint between arm_0_link and arm_1_link -->
  <joint name="arm1_joint_1" type="revolute">
    <origin rpy="0 0 2.96705972839" xyz="0.024 0 0.096"/>
    <parent link="arm1_link_0"/>
    <child link="arm1_link_1"/>
    <axis xyz="0 0 -1"/>
    <dynamics damping="1" friction="1"/>
    <limit effort="9.5" lower="0" upper="5.89921287174" velocity="1.57079632679"/>
    <safety_controller k_position="20" k_velocity="1.51197195937" soft_lower_limit="0.001" soft_upper_limit="5.89821287174"/>
  </joint>
  <link name="arm1_link_1">
    <inertial>
      <!--See if this cause arm-jittering -->
      <!--<mass value="${link_1_mass}"/>-->
      <mass value="2.412"/>
      <!-- looks like this is not loaded try with default-->
      <!--<xacro:link_1_inertia_tensor />-->
      <inertia ixx="0.003863" ixy="-0.000979" ixz="0.000000" iyy="0.006196" iyz="0.000000" izz="0.006369"/>
    </inertial>
    <visual>
      <origin rpy="0 0 0" xyz="0 0 0"/>
      <geometry>
        <mesh filename="package://luh_youbot_description/meshes/youbot_arm/arm1.dae"/>
      </geometry>
    </visual>
    <collision>
      <origin rpy="0 0 0" xyz="0 0 0"/>
      <geometry>
        <mesh filename="package://luh_youbot_description/meshes/youbot_arm/arm1_convex.dae"/>
      </geometry>
    </collision>
  </link>
  <!-- joint between arm_1_link and arm_2_link -->
  <joint name="arm1_joint_2" type="revolute">
    <origin rpy="0 -1.1344640138 0" xyz="0.033 0 0.019"/>
    <parent link="arm1_link_1"/>
    <child link="arm1_link_2"/>
    <axis xyz="0 1 0"/>
    <dynamics damping="1" friction="1"/>
    <limit effort="9.5" lower="0" upper="2.70526034059" velocity="1.57079632679"/>
    <safety_controller k_position="20" k_velocity="6.04788783749" soft_lower_limit="0.001" soft_upper_limit="2.70426034059"/>
  </joint>
  <link name="arm1_link_2">
    <inertial>
      <!--See if this cause arm-jittering -->
      <!--<mass value="${link_2_mass}"/>-->
      <mass value="1.155"/>
      <!--<xacro:link_2_inertia_tensor />-->
      <inertia ixx="0.000823" ixy="0.000000" ixz="-0.000000" iyy="0.004447" iyz="0.000000" izz="0.004439"/>
    </inertial>
    <visual>
      <origin rpy="0 0 0" xyz="0 -0.032 0.078"/>
      <geometry>
        <mesh filename="package://luh_youbot_description/meshes/youbot_arm/arm2.dae"/>
      </geometry>
      <material name="Orange"/>
    </visual>
    <collision>
      <origin rpy="0 0 0" xyz="0 -0.032 0.078"/>
      <geometry>
        <mesh filename="package://luh_youbot_description/meshes/youbot_arm/arm2_convex.dae"/>
      </geometry>
    </collision>
  </link>
  <!-- joint between arm_2_link and arm_3_link -->
  <joint name="arm1_joint_3" type="revolute">
    <origin rpy="0 2.54818070791 0" xyz="0.000 0.000 0.155"/>
    <parent link="arm1_link_2"/>
    <child link="arm1_link_3"/>
    <axis xyz="0 1 0"/>
    <dynamics damping="1" friction="1"/>
    <limit effort="6.0" lower="-5.18362787842" upper="0" velocity="1.57079632679"/>
    <safety_controller k_position="20" k_velocity="50" soft_lower_limit="-5.18262787842" soft_upper_limit="-0.001"/>
  </joint>
  <link name="arm1_link_3">
    <inertial>
      <!--See if this cause arm-jittering -->
      <!--<mass value="${link_3_mass}"/>-->
      <mass value="0.934"/>
      <!--<xacro:link_3_inertia_tensor />-->
      <inertia ixx="0.002459" ixy="0.000000" ixz="0.000000" iyy="0.002571" iyz="-0.000000" izz="0.000535"/>
    </inertial>
    <visual>
      <origin rpy="0 0 0" xyz="0.000 0.028 0.079"/>
      <geometry>
        <mesh filename="package://luh_youbot_description/meshes/youbot_arm/arm3.dae"/>
      </geometry>
      <material name="Orange"/>
    </visual>
    <collision>
      <origin rpy="0 0 0" xyz="0.000 0.028 0.079"/>
      <geometry>
        <mesh filename="package://luh_youbot_description/meshes/youbot_arm/arm3_convex.dae"/>
      </geometry>
    </collision>
  </link>
  <!-- joint between arm_3_link and arm_4_link -->
  <joint name="arm1_joint_4" type="revolute">
    <origin rpy="0 -1.78896248329 0" xyz="0.000 0.000 0.135"/>
    <parent link="arm1_link_3"/>
    <child link="arm1_link_4"/>
    <axis xyz="0 1 0"/>
    <dynamics damping="1" friction="1"/>
    <limit effort="2.0" lower="0" upper="3.57792496659" velocity="1.57079632679"/>
    <safety_controller k_position="20" k_velocity="100" soft_lower_limit="0" soft_upper_limit="3.57692496659"/>
  </joint>
  <link name="arm1_link_4">
    <inertial>
      <!--See if this cause arm-jittering -->
      <!--<mass value="${link_4_mass}"/>-->
      <mass value="0.877"/>
      <!--<xacro:link_4_inertia_tensor />-->
      <inertia ixx="0.000869" ixy="0.000000" ixz="-0.000000" iyy="0.001173" iyz="-0.000231" izz="0.001091"/>
    </inertial>
    <visual>
      <origin rpy="0 0 0" xyz="0 -0.010 0.029"/>
      <geometry>
        <mesh filename="package://luh_youbot_description/meshes/youbot_arm/arm4.dae"/>
      </geometry>
      <material name="Orange"/>
    </visual>
    <collision>
      <origin rpy="0 0 0" xyz="0 -0.010 0.029"/>
      <geometry>
        <mesh filename="package://luh_youbot_description/meshes/youbot_arm/arm4_convex.dae"/>
      </geometry>
    </collision>
  </link>
  <!-- joint between arm_4_link and arm_5_link -->
  <joint name="arm1_joint_5" type="revolute">
    <origin rpy="0 0 2.92342649709" xyz="-0.002 0 0.130"/>
    <parent link="arm1_link_4"/>
    <child link="arm1_link_5"/>
    <axis xyz="0 0 -1"/>
    <dynamics damping="1" friction="1"/>
    <limit effort="1" lower="0" upper="5.84685299418" velocity="1.57079632679"/>
    <safety_controller k_position="20" k_velocity="100" soft_lower_limit="0" soft_upper_limit="5.84585299418"/>
  </joint>
  <link name="arm1_link_5">
    <inertial>
      <!--See if this cause arm-jittering -->
      <!--<mass value="${link_5_mass}"/>-->
      <mass value="0.251"/>
      <!--<xacro:link_5_inertia_tensor />-->
      <inertia ixx="0.000280" ixy="0.000000" ixz="0.000000" iyy="0.000339" iyz="0.000000" izz="0.000119"/>
    </inertial>
    <visual>
      <origin rpy="0 0 0" xyz="0.003 0 -0.034"/>
      <geometry>
        <mesh filename="package://luh_youbot_description/meshes/youbot_arm/arm5_new.dae"/>
      </geometry>
    </visual>
    <collision>
      <origin rpy="0 0 0" xyz="0.003 0 -0.034"/>
      <geometry>
        <mesh filename="package://luh_youbot_description/meshes/youbot_arm/arm5_new_convex.dae"/>
      </geometry>
    </collision>
  </link>

  <gazebo>
    <plugin filename="libyoubot_arm_1_controller.so" name="arm_controller1">
      <namespace>gazebo_1</namespace>
    </plugin>
  </gazebo>

  <!-- joint between arm_7_link and sdh_palm_link -->
  <joint name="gripper_palm_joint" type="fixed">
    <origin rpy="0 0 0" xyz="0 0 0"/>
    <parent link="arm1_link_5"/>
    <child link="gripper_palm_link1"/>
  </joint>
  <link name="gripper_palm_link1">
    <inertial>
      <origin rpy="0 0 0" xyz="0 0 0"/>
      <mass value="0.1"/>
      <inertia ixx="0.01" ixy="0" ixz="0" iyy="0.01" iyz="0" izz="0.01"/>
    </inertial>
    <visual>
      <origin rpy="0 -1.57079632679 1.57079632679" xyz="0 0 -0.0139"/>
      <geometry>
        <mesh filename="package://luh_youbot_description/meshes/youbot_gripper/palm.dae"/>
      </geometry>
    </visual>
  >  <collision>
      <origin rpy="0 0 0" xyz="0.003 0 0.01"/>
      <geometry>
        <!-- <mesh filename="package://luh_youbot_description/meshes/youbot_gripper/palm_convex.dae"/> -->
      <box size="0.0001 0.0001 0.0001" />
      </geometry>
    </collision>
  </link>
  <joint name="gripper_finger_joint_l" type="prismatic">
    <origin rpy="0 0 3.14159265359" xyz="0.004 0.007 0.0115"/>
    <parent link="gripper_palm_link1"/>
    <child link="gripper_finger_link_l"/>
    <axis xyz="0 -1 0"/>
    <dynamics damping="1.0" friction="1.0"/>
    <limit effort="1" lower="0" upper="0.04" velocity="0.1"/>
    <safety_controller k_position="20" k_velocity="25" soft_lower_limit="0.001" soft_upper_limit="0.0295"/>
  </joint>
  
      <gazebo reference="gripper_finger_joint_l">
    <implicitSpringDamper>1</implicitSpringDamper>
  </gazebo>

  <link name="gripper_finger_link_l">
    <inertial>
      <origin rpy="0 0 0" xyz="0 0.00 0"/>
      <mass value="0.01"/>
      <inertia ixx="0.01" ixy="0" ixz="0" iyy="0.01" iyz="0" izz="0.01"/>
    </inertial>
    <visual>
      <origin rpy="0 -1.57079632679 0" xyz="0 0 0"/>
      <!---->
      <geometry>
        <mesh filename="package://luh_youbot_description/meshes/youbot_gripper/finger.dae"/>
      </geometry>
    </visual>
    >
    <collision>
      <origin rpy="0 -1.57079632679 0" xyz="0 0 0"/>
      <geometry>
        <mesh filename="package://luh_youbot_description/meshes/youbot_gripper/finger_convex.dae"/>
      </geometry>
    </collision>
  </link>
  
  <gazebo reference='gripper_finger_link_l'><maxVel>0.0</maxVel><turnGravityOff>true</turnGravityOff><fdir1>1 0 0</fdir1><kp>1000000.0</kp><kd>1.0</kd><minDepth>0.001</minDepth><mu1>500.0</mu1>
        <mu2>500.0</mu2></gazebo>
    
  <joint name="gripper_finger_joint_r" type="prismatic">
    <origin rpy="0 0 0" xyz="0.004 -0.007 0.0115"/>
    <parent link="gripper_palm_link1"/>
    <child link="gripper_finger_link_r"/>
    <axis xyz="0 -1 0"/>
    <dynamics damping="1.0" friction="1.0"/>
    <limit effort="1" lower="0" upper="0.04" velocity="0.1"/>
    <safety_controller k_position="20" k_velocity="25" soft_lower_limit="0.001" soft_upper_limit="0.0295"/>
  </joint>

    <gazebo reference="gripper_finger_joint_r">
    <implicitSpringDamper>1</implicitSpringDamper>
  </gazebo>

  <link name="gripper_finger_link_r">
    <inertial>
      <origin rpy="0 0 0" xyz="0.000 -0.001 0"/>
      <mass value="0.01"/>
      <inertia ixx="0.01" ixy="0" ixz="0" iyy="0.01" iyz="0" izz="0.01"/>
    </inertial>
    <visual>
      <origin rpy="0 -1.57079632679 0" xyz="0 0 0"/>
      <!-- -->
      <geometry>
        <mesh filename="package://luh_youbot_description/meshes/youbot_gripper/finger.dae"/>
      </geometry>
    </visual>
    <collision>
      <origin rpy="0 -1.57079632679 0" xyz="0 0 0"/>
      <geometry>
        <mesh filename="package://luh_youbot_description/meshes/youbot_gripper/finger_convex.dae"/>
      </geometry>
    </collision>
  </link>

  <gazebo reference='gripper_finger_link_r'><maxVel>0.0</maxVel><turnGravityOff>true</turnGravityOff><fdir1>1 0 0</fdir1><kp>1000000.0</kp><kd>1.0</kd><minDepth>0.001</minDepth><mu1>500.0</mu1>
        <mu2>500.0</mu2>
  </gazebo>
  <!-- coordinate frame on the tip of the robot's gripper -->
  <joint name="gripper_tip_joint" type="fixed">
    <origin rpy="0.0 -1.57079632679 0.0" xyz="0.000 0 0.09"/>
    <parent link="gripper_palm_link1"/>
    <child link="gripper_tip1"/>
  </joint>
  <link name="gripper_tip1">
    <inertial>
      <mass value="0.001"/>
      <origin xyz="0 0 0"/>
      <inertia ixx="0.001" ixy="0.0" ixz="0.0" iyy="0.001" iyz="0.0" izz="0.001"/>
    </inertial>
  </link>

  <gazebo>
    <plugin filename="libyoubot_gripper_1_controller.so" name="gripper_controller_1">
      <namespace></namespace>
    </plugin>
  </gazebo>
 
  <!-- Kamera -->
  <!--xacro:include filename="$(find luh_youbot_description)/urdf/sensors/asus_xtion_camera.urdf.xacro" />

  <xacro:asus_xtion_camera name="camera" parent="arm_link_5" tilt="0.0">
    <origin xyz="-0.02 0 -0.04" rpy="0 -1.60 0" />

    <inertia ixx="0.1" ixy="0" ixz="0" iyy="0.1" iyz="0" izz="0.1" />

  </xacro:asus_xtion_camera-->

  <gazebo>
    <plugin filename="libyoubot_joint_state_publisher.so" name="youbot_joint_state_publisher_1">
      <robotNamespace>gazebo_1</robotNamespace>
      <updateRate>100.0</updateRate>
      <alwaysOn>true</alwaysOn>
    </plugin>
  </gazebo>

  <gazebo>
		<plugin name="gazebo_grasp_fix" filename="libgazebo_grasp_fix.so">
			
            <arm>
                <arm_name>youbot1</arm_name>
                <palm_link>arm1_link_5</palm_link>
                <gripper_link>gripper_finger_link_r</gripper_link>
                <gripper_link>gripper_finger_link_l</gripper_link>
                
            </arm>
			<forces_angle_tolerance>100</forces_angle_tolerance>
			<update_rate>4</update_rate>
			<grip_count_threshold>4</grip_count_threshold>
			<max_grip_count>8</max_grip_count>
			<release_tolerance>0.005</release_tolerance>
			<disable_collisions_on_attach>false</disable_collisions_on_attach>
			<contact_topic>__default_topic__</contact_topic>
		</plugin>
	</gazebo>

</robot>
